<?xml version="1.0" ?>
<robot name="dyros_avatar_haptic">

<mujoco>
      <compiler 
      meshdir="../meshes/" 
      balanceinertia="true" 
      discardvisual="false" />
</mujoco>

<material name="silver">
  <color rgba="0.700 0.700 0.700 1.000"/>
</material>

<link name="base_link">
</link>

<!-- RIGHT -->
<joint name="base_footprint_joint_right" type="fixed">
  <origin rpy="0 0 0" xyz="0 -0.5 0.0"/>
  <parent link="base_link"/>
  <child link="R0v2_1"/>
</joint>

<link name="R0v2_1">
  <inertial>
    <origin xyz="-0.022028950404033087 0.05827830226084317 0.4460709796209712" rpy="0 0 0"/>
    <mass value="54.47494543793283"/>
    <inertia ixx="17.852652" iyy="18.178648" izz="1.124692" ixy="-0.098729" iyz="-0.067986" ixz="-0.126587"/>
  </inertial>
  <visual>
    <origin xyz="0 0 0" rpy="0 0 0"/>
    <geometry>
      <mesh filename="package://dyros_avatar_haptic_description/meshes/R0v2_1_reduced.stl" scale="0.001 0.001 0.001"/>
    </geometry>
    <material name="silver"/>
  </visual>
  <collision>
    <origin xyz="0 0 0" rpy="0 0 0"/>
    <geometry>
      <mesh filename="package://dyros_avatar_haptic_description/meshes/R0v2_1_reduced.stl" scale="0.001 0.001 0.001"/>
    </geometry>
  </collision>
</link>

<link name="R1v2_1">
  <inertial>
    <origin xyz="0.07174869274231477 0.05748257241792949 0.10425487387661325" rpy="0 0 0"/>
    <mass value="9.600608608246226"/>
    <inertia ixx="0.167071" iyy="0.229357" izz="0.083369" ixy="-0.006156" iyz="-0.006963" ixz="-0.072231"/>
  </inertial>
  <visual>
    <origin xyz="-1.2612133559741782e-15 -1.8041124150158794e-16 -0.47869999999999935" rpy="0 0 0"/>
    <geometry>
      <mesh filename="package://dyros_avatar_haptic_description/meshes/R1v2_1_reduced.stl" scale="0.001 0.001 0.001"/>
    </geometry>
    <material name="silver"/>
  </visual>
  <collision>
    <origin xyz="-1.2612133559741782e-15 -1.8041124150158794e-16 -0.47869999999999935" rpy="0 0 0"/>
    <geometry>
      <mesh filename="package://dyros_avatar_haptic_description/meshes/R1v2_1_reduced.stl" scale="0.001 0.001 0.001"/>
    </geometry>
  </collision>
</link>

<link name="R2v2_1">
  <inertial>
    <origin xyz="0.3582959901377483 -0.042077032719756755 0.0034250698006526026" rpy="0 0 0"/>
    <mass value="3.6400232117451474"/>
    <inertia ixx="0.005129" iyy="0.089011" izz="0.087967" ixy="0.003864" iyz="-0.000169" ixz="0.001574"/>
  </inertial>
  <visual>
    <origin xyz="-0.25854804549570726 -0.0640394305962068 -0.7655000000000003" rpy="0 0 0"/>
    <geometry>
      <mesh filename="package://dyros_avatar_haptic_description/meshes/R2v2_1_reduced.stl" scale="0.001 0.001 0.001"/>
    </geometry>
    <material name="silver"/>
  </visual>
  <collision>
    <origin xyz="-0.25854804549570726 -0.0640394305962068 -0.7655000000000003" rpy="0 0 0"/>
    <geometry>
      <mesh filename="package://dyros_avatar_haptic_description/meshes/R2v2_1_reduced.stl" scale="0.001 0.001 0.001"/>
    </geometry>
  </collision>
</link>

<link name="R3v2_1">
  <inertial>
    <origin xyz="0.32992945139349705 0.12421291432128218 0.021581753809667426" rpy="0 0 0"/>
    <mass value="2.275600802694944"/>
    <inertia ixx="0.018024" iyy="0.047596" izz="0.06267" ixy="-0.022601" iyz="-0.000714" ixz="-0.001"/>
  </inertial>
  <visual>
    <origin xyz="-0.7565374894861877 -0.01892276323201273 -0.8199999999999998" rpy="0 0 0"/>
    <geometry>
      <mesh filename="package://dyros_avatar_haptic_description/meshes/R3v2_1_reduced.stl" scale="0.001 0.001 0.001"/>
    </geometry>
    <material name="silver"/>
  </visual>
  <collision>
    <origin xyz="-0.7565374894861877 -0.01892276323201273 -0.8199999999999998" rpy="0 0 0"/>
    <geometry>
      <mesh filename="package://dyros_avatar_haptic_description/meshes/R3v2_1_reduced.stl" scale="0.001 0.001 0.001"/>
    </geometry>
  </collision>
</link>

<link name="R4v1_1">
  <inertial>
    <origin xyz="0.03273394152109854 -0.07843601742283265 -0.3403087511962361" rpy="0 0 0"/>
    <mass value="2.6616567255115777"/>
    <inertia ixx="0.431769" iyy="0.428963" izz="0.022215" ixy="-0.007633" iyz="0.045224" ixz="0.059202"/>
  </inertial>
  <visual>
    <origin xyz="-1.166740508971252 -0.2039733855096369 -0.8097000000000009" rpy="0 0 0"/>
    <geometry>
      <mesh filename="package://dyros_avatar_haptic_description/meshes/R4v1_1_reduced.stl" scale="0.001 0.001 0.001"/>
    </geometry>
    <material name="silver"/>
  </visual>
  <collision>
    <origin xyz="-1.166740508971252 -0.2039733855096369 -0.8097000000000009" rpy="0 0 0"/>
    <geometry>
      <mesh filename="package://dyros_avatar_haptic_description/meshes/R4v1_1_reduced.stl" scale="0.001 0.001 0.001"/>
    </geometry>
  </collision>
</link>

<link name="R5v3_1">
  <inertial>
    <origin xyz="0.003478206671689188 0.07181457569529943 0.012391219361348127" rpy="0 0 0"/>
    <mass value="1.6499764908897157"/>
    <inertia ixx="0.003237" iyy="0.00299" izz="0.003256" ixy="-8.6e-05" iyz="0.000531" ixz="8e-05"/>
  </inertial>
  <visual>
    <origin xyz="-1.1666443276190643 -0.11619843820605029 -0.6536250000000008" rpy="0 0 0"/>
    <geometry>
      <mesh filename="package://dyros_avatar_haptic_description/meshes/R5v3_1_reduced.stl" scale="0.001 0.001 0.001"/>
    </geometry>
    <material name="silver"/>
  </visual>
  <collision>
    <origin xyz="-1.1666443276190643 -0.11619843820605029 -0.6536250000000008" rpy="0 0 0"/>
    <geometry>
      <mesh filename="package://dyros_avatar_haptic_description/meshes/R5v3_1_reduced.stl" scale="0.001 0.001 0.001"/>
    </geometry>
  </collision>
</link>

<link name="R6v1_1">
  <inertial>
    <origin xyz="0.02659912498669792 0.006160314307114584 -0.04537670815322037" rpy="0 0 0"/>
    <mass value="0.29003290841142326"/>
    <inertia ixx="0.000186" iyy="0.000297" izz="0.000306" ixy="-6.2e-05" iyz="2.1e-05" ixz="7.4e-05"/>
  </inertial>
  <visual>
    <origin xyz="-1.128739901716181 -0.20344002517564377 -0.653624999999996" rpy="0 0 0"/>
    <geometry>
      <mesh filename="package://dyros_avatar_haptic_description/meshes/R6v1_1_reduced.stl" scale="0.001 0.001 0.001"/>
    </geometry>
    <material name="silver"/>
  </visual>
  <collision>
    <origin xyz="-1.128739901716181 -0.20344002517564377 -0.653624999999996" rpy="0 0 0"/>
    <geometry>
      <mesh filename="package://dyros_avatar_haptic_description/meshes/R6v1_1_reduced.stl" scale="0.001 0.001 0.001"/>
    </geometry>
  </collision>
</link>

<!-- LEFT -->
<joint name="base_footprint_joint_left" type="fixed">
  <origin rpy="0 0 0" xyz="0 0.5 0"/>
  <parent link="base_link"/>
  <child link="L0v1_1"/>
</joint>

<link name="L0v1_1">
  <inertial>
    <origin xyz="-0.05396861611301294 -0.03632116085286392 0.46986294658671324" rpy="0 0 0"/>
    <mass value="83.96706134148887"/>
    <inertia ixx="24.453447" iyy="25.002911" izz="1.749241" ixy="0.350866" iyz="0.742595" ixz="-1.055886"/>
  </inertial>
  <visual>
    <origin xyz="0 0 0" rpy="0 0 0"/>
    <geometry>
      <mesh filename="package://dyros_avatar_haptic_description/meshes/L0v1_1_reduced.stl" scale="0.001 0.001 0.001"/>
    </geometry>
    <material name="silver"/>
  </visual>
  <collision>
    <origin xyz="0 0 0" rpy="0 0 0"/>
    <geometry>
      <mesh filename="package://dyros_avatar_haptic_description/meshes/L0v1_1_reduced.stl" scale="0.001 0.001 0.001"/>
    </geometry>
  </collision>
</link>

<link name="L1v4_1">
  <inertial>
    <origin xyz="0.0741768217163413 -0.05733194522478797 0.10445031722599518" rpy="0 0 0"/>
    <mass value="9.311307466586474"/>
    <inertia ixx="0.150526" iyy="0.213928" izz="0.0834" ixy="0.006349" iyz="0.007109" ixz="-0.068318"/>
  </inertial>
  <visual>
    <origin xyz="-1.696420781627239e-15 6.128431095930863e-16 -0.4776999999999999" rpy="0 0 0"/>
    <geometry>
      <mesh filename="package://dyros_avatar_haptic_description/meshes/L1v4_1_reduced.stl" scale="0.001 0.001 0.001"/>
    </geometry>
    <material name="silver"/>
  </visual>
  <collision>
    <origin xyz="-1.696420781627239e-15 6.128431095930863e-16 -0.4776999999999999" rpy="0 0 0"/>
    <geometry>
      <mesh filename="package://dyros_avatar_haptic_description/meshes/L1v4_1_reduced.stl" scale="0.001 0.001 0.001"/>
    </geometry>
  </collision>
</link>

<link name="L2v2_1">
  <inertial>
    <origin xyz="0.36746414227304836 0.042295332140348016 0.003693903106276708" rpy="0 0 0"/>
    <mass value="3.7894327940262715"/>
    <inertia ixx="0.005322" iyy="0.089542" izz="0.088435" ixy="-0.003696" iyz="0.000149" ixz="0.001293"/>
  </inertial>
  <visual>
    <origin xyz="-0.2585000969116231 0.06409960917729854 -0.7539999999999989" rpy="0 0 0"/>
    <geometry>
      <mesh filename="package://dyros_avatar_haptic_description/meshes/L2v2_1_reduced.stl" scale="0.001 0.001 0.001"/>
    </geometry>
    <material name="silver"/>
  </visual>
  <collision>
    <origin xyz="-0.2585000969116231 0.06409960917729854 -0.7539999999999989" rpy="0 0 0"/>
    <geometry>
      <mesh filename="package://dyros_avatar_haptic_description/meshes/L2v2_1_reduced.stl" scale="0.001 0.001 0.001"/>
    </geometry>
  </collision>
</link>

<link name="L3v2_1">
  <inertial>
    <origin xyz="0.3320525649320156 -0.12592164250769314 0.021879011293097106" rpy="0 0 0"/>
    <mass value="2.2188807496265475"/>
    <inertia ixx="0.017465" iyy="0.045335" izz="0.059858" ixy="0.021676" iyz="0.000709" ixz="-0.000968"/>
  </inertial>
  <visual>
    <origin xyz="-0.7565000288761672 0.019098856257931812 -0.8084999999999993" rpy="0 0 0"/>
    <geometry>
      <mesh filename="package://dyros_avatar_haptic_description/meshes/L3v2_1_reduced.stl" scale="0.001 0.001 0.001"/>
    </geometry>
    <material name="silver"/>
  </visual>
  <collision>
    <origin xyz="-0.7565000288761672 0.019098856257931812 -0.8084999999999993" rpy="0 0 0"/>
    <geometry>
      <mesh filename="package://dyros_avatar_haptic_description/meshes/L3v2_1_reduced.stl" scale="0.001 0.001 0.001"/>
    </geometry>
  </collision>
</link>

<link name="L4v5_1">
  <inertial>
    <origin xyz="0.042746853820180286 0.12785942409349207 -0.33624402390767794" rpy="0 0 0"/>
    <mass value="2.6616567255115777"/>
    <inertia ixx="0.414198" iyy="0.420532" izz="0.025239" ixy="-0.007279" iyz="0.043137" ixz="0.075595"/>
  </inertial>
  <visual>
    <origin xyz="-1.1665003093306239 0.20459823638430413 -0.7982000000000404" rpy="0 0 0"/>
    <geometry>
      <mesh filename="package://dyros_avatar_haptic_description/meshes/L4v5_1_reduced.stl" scale="0.001 0.001 0.001"/>
    </geometry>
    <material name="silver"/>
  </visual>
  <collision>
    <origin xyz="-1.1665003093306239 0.20459823638430413 -0.7982000000000404" rpy="0 0 0"/>
    <geometry>
      <mesh filename="package://dyros_avatar_haptic_description/meshes/L4v5_1_reduced.stl" scale="0.001 0.001 0.001"/>
    </geometry>
  </collision>
</link>

<link name="L5v6_1">
  <inertial>
    <origin xyz="0.003992515116590267 -0.0718382071092748 0.012391219361361117" rpy="0 0 0"/>
    <mass value="1.6499764908897157"/>
    <inertia ixx="0.003238" iyy="0.002993" izz="0.003259" ixy="0.000102" iyz="-0.000531" ixz="8.9e-05"/>
  </inertial>
  <visual>
    <origin xyz="-1.1665001766247958 0.11682323638440481 -0.6421250000000411" rpy="0 0 0"/>
    <geometry>
      <mesh filename="package://dyros_avatar_haptic_description/meshes/L5v6_1_reduced.stl" scale="0.001 0.001 0.001"/>
    </geometry>
    <material name="silver"/>
  </visual>
  <collision>
    <origin xyz="-1.1665001766247958 0.11682323638440481 -0.6421250000000411" rpy="0 0 0"/>
    <geometry>
      <mesh filename="package://dyros_avatar_haptic_description/meshes/L5v6_1_reduced.stl" scale="0.001 0.001 0.001"/>
    </geometry>
  </collision>
</link>

<link name="L6v5_1">
  <inertial>
    <origin xyz="0.026592349362456913 0.006189497379083725 -0.04537670815320627" rpy="0 0 0"/>
    <mass value="0.29003290841142326"/>
    <inertia ixx="0.000186" iyy="0.000297" izz="0.000306" ixy="-6.2e-05" iyz="2.1e-05" ixz="7.3e-05"/>
  </inertial>
  <visual>
    <origin xyz="-1.1293003084613416 0.20402329262647853 -0.6421250000000527" rpy="0 0 0"/>
    <geometry>
      <mesh filename="package://dyros_avatar_haptic_description/meshes/L6v5_1_reduced.stl" scale="0.001 0.001 0.001"/>
    </geometry>
    <material name="silver"/>
  </visual>
  <collision>
    <origin xyz="-1.1293003084613416 0.20402329262647853 -0.6421250000000527" rpy="0 0 0"/>
    <geometry>
      <mesh filename="package://dyros_avatar_haptic_description/meshes/L6v5_1_reduced.stl" scale="0.001 0.001 0.001"/>
    </geometry>
  </collision>
</link>


<joint name="R_Rev1" type="prismatic">
  <origin xyz="1.2612133559741782e-15 1.8041124150158794e-16 0.47869999999999935" rpy="0 0 0"/>
  <parent link="R0v2_1"/>
  <child link="R1v2_1"/>
  <axis xyz="9.714451465470158e-17 -8.320398604794834e-17 1.000000000000001"/>
  <limit upper="3.14159" lower="-3.14159" effort="100" velocity="100"/>
</joint>

<joint name="R_Rev2" type="revolute">
  <origin xyz="0.258548045495706 0.06403943059620662 0.28680000000000094" rpy="0 0 0"/>
  <parent link="R1v2_1"/>
  <child link="R2v2_1"/>
  <axis xyz="0.0 0.0 1.0"/>
  <limit upper="3.14159" lower="-3.14159" effort="100" velocity="100"/>
</joint>

<joint name="R_Rev3" type="revolute">
  <origin xyz="0.49798944399048045 -0.04511666736419407 0.05449999999999955" rpy="0 0 0"/>
  <parent link="R2v2_1"/>
  <child link="R3v2_1"/>
  <axis xyz="0.0 0.0 1.0"/>
  <limit upper="3.14159" lower="-3.14159" effort="100" velocity="100"/>
</joint>

<joint name="R_Rev4" type="revolute">
  <origin xyz="0.4102030194850642 0.18505062227762417 -0.010299999999998977" rpy="0 0 0"/>
  <parent link="R3v2_1"/>
  <child link="R4v1_1"/>
  <axis xyz="0.0 0.0 1.0"/>
  <limit upper="3.14159" lower="-3.14159" effort="100" velocity="100"/>
</joint>

<joint name="R_Rev5" type="revolute">
  <origin xyz="-9.618135218758539e-05 -0.0877749473035866 -0.15607500000000007" rpy="0 0 0"/>
  <parent link="R4v1_1"/>
  <child link="R5v3_1"/>
  <axis xyz="0.0010957715999700898 0.9999993996421189 7.640945265029723e-16"/>
  <limit upper="3.14159" lower="-3.14159" effort="100" velocity="100"/>
</joint>

<joint name="R_Rev6" type="revolute">
  <origin xyz="-0.03790442590288334 0.08724158696959348 -4.773959005888173e-15" rpy="0 0 0"/>
  <parent link="R5v3_1"/>
  <child link="R6v1_1"/>
  <axis xyz="0.9999993996421241 -0.0010957715999707956 1.2327063634757942e-14"/>
  <limit upper="3.14159" lower="-3.14159" effort="100" velocity="100"/>
</joint>

<joint name="L_Rev1" type="prismatic">
  <origin xyz="1.696420781627239e-15 -6.128431095930863e-16 0.4776999999999999" rpy="0 0 0"/>
  <parent link="L0v1_1"/>
  <child link="L1v4_1"/>
  <axis xyz="0.0 0.0 1.0"/>
  <limit upper="3.14159" lower="-3.14159" effort="100" velocity="100"/>
</joint>

<joint name="L_Rev2" type="revolute">
  <origin xyz="0.2585000969116214 -0.06409960917729793 0.276299999999999" rpy="0 0 0"/>
  <parent link="L1v4_1"/>
  <child link="L2v2_1"/>
  <axis xyz="0.0 0.0 1.0"/>
  <limit upper="3.14159" lower="-3.14159" effort="100" velocity="100"/>
</joint>

<joint name="L_Rev3" type="revolute">
  <origin xyz="0.49799993196454406 0.04500075291936673 0.05450000000000044" rpy="0 0 0"/>
  <parent link="L2v2_1"/>
  <child link="L3v2_1"/>
  <axis xyz="0.0 0.0 1.0"/>
  <limit upper="3.14159" lower="-3.14159" effort="100" velocity="100"/>
</joint>

<joint name="L_Rev4" type="revolute">
  <origin xyz="0.4100002804544567 -0.18549938012637232 -0.010299999999958898" rpy="0 0 0"/>
  <parent link="L3v2_1"/>
  <child link="L4v5_1"/>
  <axis xyz="0.0 0.0 1.0"/>
  <limit upper="3.14159" lower="-3.14159" effort="100" velocity="100"/>
</joint>

<joint name="L_Rev5" type="revolute">
  <origin xyz="-1.3270582810420706e-07 0.08777499999989932 -0.1560749999999993" rpy="0 0 0"/>
  <parent link="L4v5_1"/>
  <child link="L5v6_1"/>
  <axis xyz="1.5118863886020234e-06 -0.9999999999988557 2.949330639563436e-16"/>
  <limit upper="3.14159" lower="-3.14159" effort="100" velocity="100"/>
</joint>

<joint name="L_Rev6" type="revolute">
  <origin xyz="-0.03719986816345422 -0.08720005624207372 1.1546319456101628e-14" rpy="0 0 0"/>
  <parent link="L5v6_1"/>
  <child link="L6v5_1"/>
  <axis xyz="0.9999999999988606 1.5118863825447053e-06 -1.3039890257532913e-14"/>
  <limit upper="3.14159" lower="-3.14159" effort="100" velocity="100"/>
</joint>


</robot>
