<?xml version="1.0" ?>
<robot name="dyros_avatar_haptic">

<mujoco>
      <compiler 
      meshdir="../meshes/" 
      balanceinertia="true" 
      discardvisual="false" />
</mujoco>

<material name="silver">
  <color rgba="0.700 0.700 0.700 1.000"/>
</material>

<link name="base_link">
</link>

<!-- RIGHT -->
<joint name="base_footprint_joint_right" type="fixed">
  <origin rpy="0 0 0" xyz="0 -0.5 1.0"/>
  <parent link="base_link"/>
  <child link="R0v2_1"/>
</joint>

<link name="R0v2_1">
  <inertial>
    <origin xyz="0.002224363691248139 -0.00843604486559863 -0.5178558077892146" rpy="0 0 0"/>
    <mass value="96.30275269300822"/>
    <inertia ixx="27.599897" iyy="26.791263" izz="3.404109" ixy="-0.514111" iyz="-1.896007" ixz="-1.207392"/>
  </inertial>
  <visual>
    <origin xyz="0 0 0" rpy="0 0 0"/>
    <geometry>
      <mesh filename="package://dyros_avatar_haptic_description/meshes/R0v2_1_reduced.stl" scale="0.001 0.001 0.001"/>
    </geometry>
    <material name="silver"/>
  </visual>
  <collision>
    <origin xyz="0 0 0" rpy="0 0 0"/>
    <geometry>
      <mesh filename="package://dyros_avatar_haptic_description/meshes/R0v2_1_reduced.stl" scale="0.001 0.001 0.001"/>
    </geometry>
  </collision>
</link>

<link name="R1v2_1">
  <inertial>
    <origin xyz="0.2930669554616949 -0.005125152353986358 -0.4433123956164984" rpy="0 0 0"/>
    <mass value="25.051059193207056"/>
    <inertia ixx="8.496975" iyy="9.282096" izz="0.935306" ixy="0.214887" iyz="-0.556302" ixz="1.918896"/>
  </inertial>
  <visual>
    <origin xyz="-0.06090000000000058 0.004100000000000117 -0.12220000000000049" rpy="0 0 0"/>
    <geometry>
      <mesh filename="package://dyros_avatar_haptic_description/meshes/R1v2_1_reduced.stl" scale="0.001 0.001 0.001"/>
    </geometry>
    <material name="silver"/>
  </visual>
  <collision>
    <origin xyz="-0.06090000000000058 0.004100000000000117 -0.12220000000000049" rpy="0 0 0"/>
    <geometry>
      <mesh filename="package://dyros_avatar_haptic_description/meshes/R1v2_1_reduced.stl" scale="0.001 0.001 0.001"/>
    </geometry>
  </collision>
</link>

<link name="R2v2_1">
  <inertial>
    <origin xyz="0.3578996710059897 -0.042016213116413986 0.0034825253313463533" rpy="0 0 0"/>
    <mass value="3.7157012939377037"/>
    <inertia ixx="0.005214" iyy="0.091851" izz="0.09081" ixy="0.004013" iyz="-0.000174" ixz="0.001692"/>
  </inertial>
  <visual>
    <origin xyz="-0.31944804549570677 -0.05993943059620685 -0.42350000000000093" rpy="0 0 0"/>
    <geometry>
      <mesh filename="package://dyros_avatar_haptic_description/meshes/R2v2_1_reduced.stl" scale="0.001 0.001 0.001"/>
    </geometry>
    <material name="silver"/>
  </visual>
  <collision>
    <origin xyz="-0.31944804549570677 -0.05993943059620685 -0.42350000000000093" rpy="0 0 0"/>
    <geometry>
      <mesh filename="package://dyros_avatar_haptic_description/meshes/R2v2_1_reduced.stl" scale="0.001 0.001 0.001"/>
    </geometry>
  </collision>
</link>

<link name="R3v2_1">
  <inertial>
    <origin xyz="0.3278281939725256 0.12315320854403208 0.021505999574119417" rpy="0 0 0"/>
    <mass value="2.303655764107939"/>
    <inertia ixx="0.018321" iyy="0.049325" izz="0.064687" ixy="-0.023281" iyz="-0.00073" ixz="-0.001037"/>
  </inertial>
  <visual>
    <origin xyz="-0.817437489486188 -0.014822763232013252 -0.47800000000000104" rpy="0 0 0"/>
    <geometry>
      <mesh filename="package://dyros_avatar_haptic_description/meshes/R3v2_1_reduced.stl" scale="0.001 0.001 0.001"/>
    </geometry>
    <material name="silver"/>
  </visual>
  <collision>
    <origin xyz="-0.817437489486188 -0.014822763232013252 -0.47800000000000104" rpy="0 0 0"/>
    <geometry>
      <mesh filename="package://dyros_avatar_haptic_description/meshes/R3v2_1_reduced.stl" scale="0.001 0.001 0.001"/>
    </geometry>
  </collision>
</link>

<link name="R4v2_1">
  <inertial>
    <origin xyz="-0.00023141778643842592 -0.20550475832358545 -0.3380061561135792" rpy="0 0 0"/>
    <mass value="2.438818217989082"/>
    <inertia ixx="0.108462" iyy="0.094361" izz="0.015916" ixy="-1.6e-05" iyz="-0.027303" ixz="-3.2e-05"/>
  </inertial>
  <visual>
    <origin xyz="-1.2276405089712532 -0.19987338550963582 -0.46770000000000167" rpy="0 0 0"/>
    <geometry>
      <mesh filename="package://dyros_avatar_haptic_description/meshes/R4v2_1_reduced.stl" scale="0.001 0.001 0.001"/>
    </geometry>
    <material name="silver"/>
  </visual>
  <collision>
    <origin xyz="-1.2276405089712532 -0.19987338550963582 -0.46770000000000167" rpy="0 0 0"/>
    <geometry>
      <mesh filename="package://dyros_avatar_haptic_description/meshes/R4v2_1_reduced.stl" scale="0.001 0.001 0.001"/>
    </geometry>
  </collision>
</link>

<link name="R5v2_1">
  <inertial>
    <origin xyz="0.2815058277253546 0.14069264650019758 -2.0404045668926882e-05" rpy="0 0 0"/>
    <mass value="2.1494348901715434"/>
    <inertia ixx="0.016779" iyy="0.03329" izz="0.048989" ixy="-0.018161" iyz="2e-06" ixz="4e-06"/>
  </inertial>
  <visual>
    <origin xyz="-1.2274140129815416 0.006826490396390517 0.013799999999998815" rpy="0 0 0"/>
    <geometry>
      <mesh filename="package://dyros_avatar_haptic_description/meshes/R5v2_1.stl" scale="0.001 0.001 0.001"/>
    </geometry>
    <material name="silver"/>
  </visual>
  <collision>
    <origin xyz="-1.2274140129815416 0.006826490396390517 0.013799999999998815" rpy="0 0 0"/>
    <geometry>
      <mesh filename="package://dyros_avatar_haptic_description/meshes/R5v2_1.stl" scale="0.001 0.001 0.001"/>
    </geometry>
  </collision>
</link>

<link name="R6v3_1">
  <inertial>
    <origin xyz="-0.2517999308797463 -0.06386020868518197 0.013531629068643995" rpy="0 0 0"/>
    <mass value="1.824291703230706"/>
    <inertia ixx="0.007576" iyy="0.01806" izz="0.021641" ixy="0.001168" iyz="-0.001045" ixz="0.001795"/>
  </inertial>
  <visual>
    <origin xyz="-1.5356386804036282 -0.19803588875738437 0.01380000000001743" rpy="0 0 0"/>
    <geometry>
      <mesh filename="package://dyros_avatar_haptic_description/meshes/R6v3_1.stl" scale="0.001 0.001 0.001"/>
    </geometry>
    <material name="silver"/>
  </visual>
  <collision>
    <origin xyz="-1.5356386804036282 -0.19803588875738437 0.01380000000001743" rpy="0 0 0"/>
    <geometry>
      <mesh filename="package://dyros_avatar_haptic_description/meshes/R6v3_1.stl" scale="0.001 0.001 0.001"/>
    </geometry>
  </collision>
</link>

<!-- LEFT -->
<joint name="base_footprint_joint_left" type="fixed">
  <origin rpy="0 0 0" xyz="0 0.5 0"/>
  <parent link="base_link"/>
  <child link="L0v2_1"/>
</joint>
<link name="L0v2_1">
  <inertial>
    <origin xyz="0.31538684426863983 -0.2826522922212561 0.5148629465865381" rpy="0 0 0"/>
    <mass value="83.96706134148887"/>
    <inertia ixx="52.816644" iyy="37.512956" izz="42.622482" ixy="19.274544" iyz="-7.311257" ixz="4.82036"/>
  </inertial>
  <visual>
    <origin xyz="0 0 0" rpy="0 0 0"/>
    <geometry>
      <mesh filename="package://dyros_avatar_haptic_description/meshes/L0v2_1_reduced.stl" scale="0.001 0.001 0.001"/>
    </geometry>
    <material name="silver"/>
  </visual>
  <collision>
    <origin xyz="0 0 0" rpy="0 0 0"/>
    <geometry>
      <mesh filename="package://dyros_avatar_haptic_description/meshes/L0v2_1_reduced.stl" scale="0.001 0.001 0.001"/>
    </geometry>
  </collision>
</link>

<link name="L1v2_1">
  <inertial>
    <origin xyz="-0.011148116834790028 -0.01993865318088302 -1.1250333333265985" rpy="0 0 0"/>
    <mass value="24.711500367364692"/>
    <inertia ixx="24.181967" iyy="24.384944" izz="0.265506" ixy="0.049065" iyz="0.623654" ixz="-1.372701"/>
  </inertial>
  <visual>
    <origin xyz="-0.15434484425638284 -0.04789605532138844 -1.1221999999997916" rpy="0 0 0"/>
    <geometry>
      <mesh filename="package://dyros_avatar_haptic_description/meshes/L1v2_1_reduced.stl" scale="0.001 0.001 0.001"/>
    </geometry>
    <material name="silver"/>
  </visual>
  <collision>
    <origin xyz="-0.15434484425638284 -0.04789605532138844 -1.1221999999997916" rpy="0 0 0"/>
    <geometry>
      <mesh filename="package://dyros_avatar_haptic_description/meshes/L1v2_1_reduced.stl" scale="0.001 0.001 0.001"/>
    </geometry>
  </collision>
</link>

<link name="L2v2_1">
  <inertial>
    <origin xyz="0.3671807675531784 0.04203849657933962 -0.011947287781814975" rpy="0 0 0"/>
    <mass value="3.81569646652048"/>
    <inertia ixx="0.056525" iyy="0.141466" izz="0.089168" ixy="-0.003682" iyz="-0.000293" ixz="-0.000244"/>
  </inertial>
  <visual>
    <origin xyz="-0.4128145815272143 0.016325863951696943 -1.4042999999998396" rpy="0 0 0"/>
    <geometry>
      <mesh filename="package://dyros_avatar_haptic_description/meshes/L2v2_1_reduced.stl" scale="0.001 0.001 0.001"/>
    </geometry>
    <material name="silver"/>
  </visual>
  <collision>
    <origin xyz="-0.4128145815272143 0.016325863951696943 -1.4042999999998396" rpy="0 0 0"/>
    <geometry>
      <mesh filename="package://dyros_avatar_haptic_description/meshes/L2v2_1_reduced.stl" scale="0.001 0.001 0.001"/>
    </geometry>
  </collision>
</link>

<link name="L3v2_1">
  <inertial>
    <origin xyz="0.33087864817586465 -0.125228056241001 0.011629488873647897" rpy="0 0 0"/>
    <mass value="2.2253234887304045"/>
    <inertia ixx="0.031901" iyy="0.060168" izz="0.061446" ixy="0.022451" iyz="0.003481" ixz="-0.004599"/>
  </inertial>
  <visual>
    <origin xyz="-0.9108357512310089 -0.028439239944659467 -1.4585999999999384" rpy="0 0 0"/>
    <geometry>
      <mesh filename="package://dyros_avatar_haptic_description/meshes/L3v2_1_reduced.stl" scale="0.001 0.001 0.001"/>
    </geometry>
    <material name="silver"/>
  </visual>
  <collision>
    <origin xyz="-0.9108357512310089 -0.028439239944659467 -1.4585999999999384" rpy="0 0 0"/>
    <geometry>
      <mesh filename="package://dyros_avatar_haptic_description/meshes/L3v2_1_reduced.stl" scale="0.001 0.001 0.001"/>
    </geometry>
  </collision>
</link>

<link name="L4v2_1">
  <inertial>
    <origin xyz="-0.001516643339102064 0.19924406379936704 -0.3476406556665341" rpy="0 0 0"/>
    <mass value="2.383022203577908"/>
    <inertia ixx="0.13763" iyy="0.111737" izz="0.029261" ixy="-0.00268" iyz="0.008741" ixz="-0.002779"/>
  </inertial>
  <visual>
    <origin xyz="-1.320748211048668 0.15725412365844577 -1.4357999999999012" rpy="0 0 0"/>
    <geometry>
      <mesh filename="package://dyros_avatar_haptic_description/meshes/L4v2_1_reduced.stl" scale="0.001 0.001 0.001"/>
    </geometry>
    <material name="silver"/>
  </visual>
  <collision>
    <origin xyz="-1.320748211048668 0.15725412365844577 -1.4357999999999012" rpy="0 0 0"/>
    <geometry>
      <mesh filename="package://dyros_avatar_haptic_description/meshes/L4v2_1_reduced.stl" scale="0.001 0.001 0.001"/>
    </geometry>
  </collision>
</link>

<link name="L5v2_1">
  <inertial>
    <origin xyz="0.2728386992656229 -0.1296734670877175 -0.013712675388114826" rpy="0 0 0"/>
    <mass value="1.9614501562414652"/>
    <inertia ixx="0.043371" iyy="0.065245" izz="0.056744" ixy="0.021412" iyz="0.007629" ixz="-0.014915"/>
  </inertial>
  <visual>
    <origin xyz="-1.3208426391568135 -0.04294585407215641 -0.9592999999999394" rpy="0 0 0"/>
    <geometry>
      <mesh filename="package://dyros_avatar_haptic_description/meshes/L5v2_1.stl" scale="0.001 0.001 0.001"/>
    </geometry>
    <material name="silver"/>
  </visual>
  <collision>
    <origin xyz="-1.3208426391568135 -0.04294585407215641 -0.9592999999999394" rpy="0 0 0"/>
    <geometry>
      <mesh filename="package://dyros_avatar_haptic_description/meshes/L5v2_1.stl" scale="0.001 0.001 0.001"/>
    </geometry>
  </collision>
</link>

<link name="L6v2_1">
  <inertial>
    <origin xyz="-0.21772762060217477 0.12457271488670181 -0.004581049927364966" rpy="0 0 0"/>
    <mass value="0.5876479968624119"/>
    <inertia ixx="0.006546" iyy="0.024761" izz="0.021623" ixy="0.000154" iyz="-0.001428" ixz="-0.00677"/>
  </inertial>
  <visual>
    <origin xyz="-1.6227481774555241 0.15739656765764903 -0.9592999999999704" rpy="0 0 0"/>
    <geometry>
      <mesh filename="package://dyros_avatar_haptic_description/meshes/L6v2_1.stl" scale="0.001 0.001 0.001"/>
    </geometry>
    <material name="silver"/>
  </visual>
  <collision>
    <origin xyz="-1.6227481774555241 0.15739656765764903 -0.9592999999999704" rpy="0 0 0"/>
    <geometry>
      <mesh filename="package://dyros_avatar_haptic_description/meshes/L6v2_1.stl" scale="0.001 0.001 0.001"/>
    </geometry>
  </collision>
</link>

<joint name="R_Rev1" type="prismatic">
  <origin xyz="0.06090000000000058 -0.004100000000000117 0.12220000000000049" rpy="0 0 0"/>
  <parent link="R0v2_1"/>
  <child link="R1v2_1"/>
  <axis xyz="2.6367796834847473e-16 -8.320398604795848e-17 1.0000000000000007"/>
  <limit upper="3.14159" lower="-3.14159" effort="100" velocity="100"/>
</joint>

<joint name="R_Rev2" type="revolute">
  <origin xyz="0.2585480454957062 0.06403943059620697 0.30130000000000046" rpy="0 0 0"/>
  <parent link="R1v2_1"/>
  <child link="R2v2_1"/>
  <axis xyz="1.1489890949413866e-15 -4.0963920219047034e-16 -1.0"/>
  <limit upper="3.14159" lower="-3.14159" effort="100" velocity="100"/>
</joint>

<joint name="R_Rev3" type="revolute">
  <origin xyz="0.49798944399048123 -0.0451166673641936 0.054500000000000104" rpy="0 0 0"/>
  <parent link="R2v2_1"/>
  <child link="R3v2_1"/>
  <axis xyz="-1.015837663818999e-16 -3.522754464334303e-16 -1.000000000000001"/>
  <limit upper="3.14159" lower="-3.14159" effort="100" velocity="100"/>
</joint>

<joint name="R_Rev4" type="revolute">
  <origin xyz="0.4102030194850652 0.18505062227762256 -0.010299999999999365" rpy="0 0 0"/>
  <parent link="R3v2_1"/>
  <child link="R4v2_1"/>
  <axis xyz="2.1372581707861384e-16 -3.967117874549952e-16 -1.000000000000002"/>
  <limit upper="3.14159" lower="-3.14159" effort="100" velocity="100"/>
</joint>

<joint name="R_Rev5" type="revolute">
  <origin xyz="-0.0002264959897115837 -0.20669987590602634 -0.4815000000000005" rpy="0 0 0"/>
  <parent link="R4v2_1"/>
  <child link="R5v2_1"/>
  <axis xyz="0.001095771599960823 0.9999993996421215 2.3141483428879694e-16"/>
  <limit upper="3.14159" lower="-3.14159" effort="100" velocity="100"/>
</joint>

<joint name="R_Rev6" type="revolute">
  <origin xyz="0.30822466742208654 0.2048623791537749 -1.8615317620707117e-14" rpy="0 0 0"/>
  <parent link="R5v2_1"/>
  <child link="R6v3_1"/>
  <axis xyz="0.9999993996421225 -0.001095771599961881 3.594176539271707e-16"/>
  <limit upper="3.14159" lower="-3.14159" effort="100" velocity="100"/>
</joint>

<joint name="L_Rev1" type="prismatic">
  <origin xyz="0.15434484425638284 0.04789605532138844 1.1221999999997916" rpy="0 0 0"/>
  <parent link="L0v2_1"/>
  <child link="L1v2_1"/>
  <axis xyz="-1.9785965043687577e-13 4.98557253978501e-16 0.999999999999999"/>
  <limit upper="3.14159" lower="-3.14159" effort="100" velocity="100"/>
</joint>

<joint name="L_Rev2" type="revolute">
  <origin xyz="0.25846973727083145 -0.06422191927308538 0.282100000000048" rpy="0 0 0"/>
  <parent link="L1v2_1"/>
  <child link="L2v2_1"/>
  <axis xyz="-1.9809494050748165e-13 4.918921006832097e-16 0.9999999999999986"/>
  <limit upper="3.14159" lower="-3.14159" effort="100" velocity="100"/>
</joint>

<joint name="L_Rev3" type="revolute">
  <origin xyz="0.4980211697037946 0.044765103896356406 0.054300000000098825" rpy="0 0 0"/>
  <parent link="L2v2_1"/>
  <child link="L3v2_1"/>
  <axis xyz="1.9816330287697064e-13 -4.919243450884573e-16 -0.999999999999999"/>
  <limit upper="3.14159" lower="-3.14159" effort="100" velocity="100"/>
</joint>

<joint name="L_Rev4" type="revolute">
  <origin xyz="0.409912459817659 -0.18569336360310523 -0.022800000000037235" rpy="0 0 0"/>
  <parent link="L3v2_1"/>
  <child link="L4v2_1"/>
  <axis xyz="-1.264349999867203e-13 -1.5138091700230881e-13 -0.9999999999999986"/>
  <limit upper="3.14159" lower="-3.14159" effort="100" velocity="100"/>
</joint>

<joint name="L_Rev5" type="revolute">
  <origin xyz="9.442810814563884e-05 0.20019997773060216 -0.47649999999996173" rpy="0 0 0"/>
  <parent link="L4v2_1"/>
  <child link="L5v2_1"/>
  <axis xyz="-0.00047166887155364285 -0.9999998887642285 -7.445754955941802e-14"/>
  <limit upper="3.14159" lower="-3.14159" effort="100" velocity="100"/>
</joint>

<joint name="L_Rev6" type="revolute">
  <origin xyz="0.3019055382987106 -0.20034242172980543 3.097522238704187e-14" rpy="0 0 0"/>
  <parent link="L5v2_1"/>
  <child link="L6v2_1"/>
  <axis xyz="0.9999998887642307 -0.0004716688715537389 1.5182680658618058e-13"/>
  <limit upper="3.14159" lower="-3.14159" effort="100" velocity="100"/>
</joint>


</robot>
