<?xml version="1.0" ?>
<robot name="dyros_avatar_haptic">

<mujoco>
      <compiler 
      meshdir="../meshes/" 
      balanceinertia="true" 
      discardvisual="false" />
</mujoco>

<material name="silver">
  <color rgba="0.700 0.700 0.700 1.000"/>
</material>

<link name="base_link">
</link>

<joint name="base_footprint_joint" type="fixed">
  <origin rpy="0 0 0" xyz="0 -0.5 0.0"/>
  <parent link="base_link"/>
  <child link="R0v2_1"/>
</joint>

<link name="R0v2_1">
  <inertial>
    <origin xyz="-0.022028950404033087 0.05827830226084317 0.4460709796209712" rpy="0 0 0"/>
    <mass value="54.47494543793283"/>
    <inertia ixx="17.852652" iyy="18.178648" izz="1.124692" ixy="-0.098729" iyz="-0.067986" ixz="-0.126587"/>
  </inertial>
  <visual>
    <origin xyz="0 0 0" rpy="0 0 0"/>
    <geometry>
      <mesh filename="package://dyros_avatar_haptic_description/meshes/R0v2_1_reduced.stl" scale="0.001 0.001 0.001"/>
    </geometry>
    <material name="silver"/>
  </visual>
  <collision>
    <origin xyz="0 0 0" rpy="0 0 0"/>
    <geometry>
      <mesh filename="package://dyros_avatar_haptic_description/meshes/R0v2_1_reduced.stl" scale="0.001 0.001 0.001"/>
    </geometry>
  </collision>
</link>

<link name="R1v2_1">
  <inertial>
    <origin xyz="0.07174869274231477 0.05748257241792949 0.10425487387661325" rpy="0 0 0"/>
    <mass value="9.600608608246226"/>
    <inertia ixx="0.167071" iyy="0.229357" izz="0.083369" ixy="-0.006156" iyz="-0.006963" ixz="-0.072231"/>
  </inertial>
  <visual>
    <origin xyz="-1.2612133559741782e-15 -1.8041124150158794e-16 -0.47869999999999935" rpy="0 0 0"/>
    <geometry>
      <mesh filename="package://dyros_avatar_haptic_description/meshes/R1v2_1.stl" scale="0.001 0.001 0.001"/>
    </geometry>
    <material name="silver"/>
  </visual>
  <collision>
    <origin xyz="-1.2612133559741782e-15 -1.8041124150158794e-16 -0.47869999999999935" rpy="0 0 0"/>
    <geometry>
      <mesh filename="package://dyros_avatar_haptic_description/meshes/R1v2_1.stl" scale="0.001 0.001 0.001"/>
    </geometry>
  </collision>
</link>

<link name="R2v2_1">
  <inertial>
    <origin xyz="0.3582959901377483 -0.042077032719756755 0.0034250698006526026" rpy="0 0 0"/>
    <mass value="3.6400232117451474"/>
    <inertia ixx="0.005129" iyy="0.089011" izz="0.087967" ixy="0.003864" iyz="-0.000169" ixz="0.001574"/>
  </inertial>
  <visual>
    <origin xyz="-0.25854804549570726 -0.0640394305962068 -0.7655000000000003" rpy="0 0 0"/>
    <geometry>
      <mesh filename="package://dyros_avatar_haptic_description/meshes/R2v2_1.stl" scale="0.001 0.001 0.001"/>
    </geometry>
    <material name="silver"/>
  </visual>
  <collision>
    <origin xyz="-0.25854804549570726 -0.0640394305962068 -0.7655000000000003" rpy="0 0 0"/>
    <geometry>
      <mesh filename="package://dyros_avatar_haptic_description/meshes/R2v2_1.stl" scale="0.001 0.001 0.001"/>
    </geometry>
  </collision>
</link>

<link name="R3v2_1">
  <inertial>
    <origin xyz="0.32992945139349705 0.12421291432128218 0.021581753809667426" rpy="0 0 0"/>
    <mass value="2.275600802694944"/>
    <inertia ixx="0.018024" iyy="0.047596" izz="0.06267" ixy="-0.022601" iyz="-0.000714" ixz="-0.001"/>
  </inertial>
  <visual>
    <origin xyz="-0.7565374894861877 -0.01892276323201273 -0.8199999999999998" rpy="0 0 0"/>
    <geometry>
      <mesh filename="package://dyros_avatar_haptic_description/meshes/R3v2_1.stl" scale="0.001 0.001 0.001"/>
    </geometry>
    <material name="silver"/>
  </visual>
  <collision>
    <origin xyz="-0.7565374894861877 -0.01892276323201273 -0.8199999999999998" rpy="0 0 0"/>
    <geometry>
      <mesh filename="package://dyros_avatar_haptic_description/meshes/R3v2_1.stl" scale="0.001 0.001 0.001"/>
    </geometry>
  </collision>
</link>

<link name="R4v1_1">
  <inertial>
    <origin xyz="0.03273394152109854 -0.07843601742283265 -0.3403087511962361" rpy="0 0 0"/>
    <mass value="2.6616567255115777"/>
    <inertia ixx="0.431769" iyy="0.428963" izz="0.022215" ixy="-0.007633" iyz="0.045224" ixz="0.059202"/>
  </inertial>
  <visual>
    <origin xyz="-1.166740508971252 -0.2039733855096369 -0.8097000000000009" rpy="0 0 0"/>
    <geometry>
      <mesh filename="package://dyros_avatar_haptic_description/meshes/R4v1_1.stl" scale="0.001 0.001 0.001"/>
    </geometry>
    <material name="silver"/>
  </visual>
  <collision>
    <origin xyz="-1.166740508971252 -0.2039733855096369 -0.8097000000000009" rpy="0 0 0"/>
    <geometry>
      <mesh filename="package://dyros_avatar_haptic_description/meshes/R4v1_1.stl" scale="0.001 0.001 0.001"/>
    </geometry>
  </collision>
</link>

<link name="R5v3_1">
  <inertial>
    <origin xyz="0.003478206671689188 0.07181457569529943 0.012391219361348127" rpy="0 0 0"/>
    <mass value="1.6499764908897157"/>
    <inertia ixx="0.003237" iyy="0.00299" izz="0.003256" ixy="-8.6e-05" iyz="0.000531" ixz="8e-05"/>
  </inertial>
  <visual>
    <origin xyz="-1.1666443276190643 -0.11619843820605029 -0.6536250000000008" rpy="0 0 0"/>
    <geometry>
      <mesh filename="package://dyros_avatar_haptic_description/meshes/R5v3_1.stl" scale="0.001 0.001 0.001"/>
    </geometry>
    <material name="silver"/>
  </visual>
  <collision>
    <origin xyz="-1.1666443276190643 -0.11619843820605029 -0.6536250000000008" rpy="0 0 0"/>
    <geometry>
      <mesh filename="package://dyros_avatar_haptic_description/meshes/R5v3_1.stl" scale="0.001 0.001 0.001"/>
    </geometry>
  </collision>
</link>

<link name="EE">
  <inertial>
    <origin xyz="0.02659912498669792 0.006160314307114584 -0.04537670815322037" rpy="0 0 0"/>
    <mass value="0.29003290841142326"/>
    <inertia ixx="0.000186" iyy="0.000297" izz="0.000306" ixy="-6.2e-05" iyz="2.1e-05" ixz="7.4e-05"/>
  </inertial>
  <visual>
    <origin xyz="-1.128739901716181 -0.20344002517564377 -0.653624999999996" rpy="0 0 0"/>
    <geometry>
      <mesh filename="package://dyros_avatar_haptic_description/meshes/R6v1_1.stl" scale="0.001 0.001 0.001"/>
    </geometry>
    <material name="silver"/>
  </visual>
  <collision>
    <origin xyz="-1.128739901716181 -0.20344002517564377 -0.653624999999996" rpy="0 0 0"/>
    <geometry>
      <mesh filename="package://dyros_avatar_haptic_description/meshes/R6v1_1.stl" scale="0.001 0.001 0.001"/>
    </geometry>
  </collision>
</link>

<joint name="Rev1" type="prismatic">
  <origin xyz="1.2612133559741782e-15 1.8041124150158794e-16 0.47869999999999935" rpy="0 0 0"/>
  <parent link="R0v2_1"/>
  <child link="R1v2_1"/>
  <axis xyz="9.714451465470158e-17 -8.320398604794834e-17 1.000000000000001"/>
  <limit upper="3.14159" lower="-3.14159" effort="100" velocity="100"/>
</joint>

<joint name="Rev2" type="revolute">
  <origin xyz="0.258548045495706 0.06403943059620662 0.28680000000000094" rpy="0 0 0"/>
  <parent link="R1v2_1"/>
  <child link="R2v2_1"/>
  <axis xyz="0.0 0.0 1.0"/>
  <limit upper="3.14159" lower="-3.14159" effort="100" velocity="100"/>
</joint>

<joint name="Rev3" type="revolute">
  <origin xyz="0.49798944399048045 -0.04511666736419407 0.05449999999999955" rpy="0 0 0"/>
  <parent link="R2v2_1"/>
  <child link="R3v2_1"/>
  <axis xyz="0.0 0.0 1.0"/>
  <limit upper="3.14159" lower="-3.14159" effort="100" velocity="100"/>
</joint>

<joint name="Rev4" type="revolute">
  <origin xyz="0.4102030194850642 0.18505062227762417 -0.010299999999998977" rpy="0 0 0"/>
  <parent link="R3v2_1"/>
  <child link="R4v1_1"/>
  <axis xyz="0.0 0.0 1.0"/>
  <limit upper="3.14159" lower="-3.14159" effort="100" velocity="100"/>
</joint>

<joint name="Rev5" type="revolute">
  <origin xyz="-9.618135218758539e-05 -0.0877749473035866 -0.15607500000000007" rpy="0 0 0"/>
  <parent link="R4v1_1"/>
  <child link="R5v3_1"/>
  <axis xyz="0.0010957715999700898 0.9999993996421189 7.640945265029723e-16"/>
  <limit upper="3.14159" lower="-3.14159" effort="100" velocity="100"/>
</joint>

<joint name="Rev6" type="revolute">
  <origin xyz="-0.03790442590288334 0.08724158696959348 -4.773959005888173e-15" rpy="0 0 0"/>
  <parent link="R5v3_1"/>
  <child link="EE"/>
  <axis xyz="0.9999993996421241 -0.0010957715999707956 1.2327063634757942e-14"/>
  <limit upper="3.14159" lower="-3.14159" effort="100" velocity="100"/>
</joint>

</robot>
