<mujoco model="asm_arm">
    <compiler angle="radian" />
    <size njmax="500" nconmax="100" />
    <asset>
        <mesh name="link_00v1_1" file="../meshes/link_00v1_1.stl" scale="0.001 0.001 0.001" />
        <mesh name="link_01v1_1_3dless_com_simplified" file="../meshes/link_01v1_1_3dless_com_simplified.stl" scale="0.001 0.001 0.001" />
        <mesh name="link_02v1_1_3dless_com_simplified" file="../meshes/link_02v1_1_3dless_com_simplified.stl" scale="0.001 0.001 0.001" />
        <mesh name="link_03v1_1_3dless_com_simplified" file="../meshes/link_03v1_1_3dless_com_simplified.stl" scale="0.001 0.001 0.001" />
        <mesh name="link_04v1_1_3dless_com_simplified" file="../meshes/link_04v1_1_3dless_com_simplified.stl" scale="0.001 0.001 0.001" />
        <mesh name="link_05v1_1_3dless_com_simplified" file="../meshes/link_05v1_1_3dless_com_simplified.stl" scale="0.001 0.001 0.001" />
        <mesh name="link_06v1_1" file="../meshes/link_06v1_1.stl" scale="0.001 0.001 0.001" />

        <material name='MatPlane' reflectance='0.3' />
    </asset>
    <worldbody>               
        <geom name="ground" type="plane" pos="0 0 0" size="30 30 .05" rgba="0.7 0.6 0.5 1" material="MatPlane" group="3"/>      
        <light directional="true" diffuse=".8 .8 .8" pos="0 0 10" dir="0 0 -10"/>
        <light directional="true" diffuse=".5 .5 .5" pos="10 0 0" dir="-10 0 0"/>

        <body name="link_00v1_1" pos="0.0 0.0 2.0">
            <inertial pos="0.1845382022698047 2.0751395377606388 -1.4808335489089286" quat="1 0 0 0" mass="96.86051357355375" diaginertia="25.951706 24.423694 6.42594" />
            <joint name="Rev2" pos="0 0 0" axis="-0.0571525 0 0.998365" type="slide" limited="true" range="-3.14159 3.14159" />
            <geom type="mesh" rgba="0.7 0.7 0.7 1" mesh="link_00v1_1" />
            <body name="link_01v1_1" pos="0.175417 2.10965 -0.956608">
                <inertial pos="0.0201713 -0.0339222 -0.346227" quat="0.779607 0.0416538 0.0253572 0.624368" mass="27.5323" diaginertia="6.91377 6.70892 0.237192" />
                <joint name="Rev3" pos="0 0 0" axis="-0.0571525 0 0.998365" limited="true" range="-3.14159 3.14159" />
                <geom pos="-0.175417 -2.10965 0.956608" type="mesh" rgba="0.7 0.7 0.7 1" mesh="link_01v1_1_3dless_com_simplified" />
                <body name="link_02v1_1" pos="0.264498 -0.0720207 0.162983">
                    <inertial pos="0.219288 -0.0494952 0.0038361" quat="0.595127 0.453682 0.535854 0.390968" mass="5.62938" diaginertia="0.0715459 0.0706911 0.00708698" />
                    <joint name="Rev4" pos="0 0 0" axis="-0.0571525 0 0.998365" limited="true" range="-3.14159 3.14159" />
                    <geom pos="-0.439915 -2.03763 0.793625" type="mesh" rgba="0.7 0.7 0.7 1" mesh="link_02v1_1_3dless_com_simplified" />
                    <body name="link_03v1_1" pos="0.325841 -0.0570551 0.062024">
                        <inertial pos="0.159845 0.139627 0.00773417" quat="0.588626 0.200276 -0.671076 0.403813" mass="3.64444" diaginertia="0.0345183 0.0339554 0.00564934" />
                        <joint name="Rev6" pos="0 0 0" axis="-0.0571525 0 0.998365" limited="true" range="-3.14159 3.14159" />
                        <geom pos="-0.765757 -1.98057 0.731601" type="mesh" rgba="0.7 0.7 0.7 1" mesh="link_03v1_1_3dless_com_simplified" />
                        <body name="link_04v1_1" pos="0.185459 0.181355 0.0512833">
                            <inertial pos="-0.0122996 -0.165696 0.150237" quat="0.937068 0.3478 -0.0306373 -0.000653688" mass="3.63822" diaginertia="0.0370155 0.0355259 0.00510459" />
                            <joint name="Rev7" pos="0 0 0" axis="0.0222389 0.999752 0.00127309" limited="true" range="-3.14159 3.14159" />
                            <geom pos="-0.951215 -2.16193 0.680318" type="mesh" rgba="0.7 0.7 0.7 1" mesh="link_04v1_1_3dless_com_simplified" />
                            <body name="link_05v1_1" pos="-0.0143863 -0.150863 0.192492">
                                <inertial pos="0.207111 0.0838408 0.0118487" quat="-0.16141 0.667357 0.170927 0.706657" mass="3.09238" diaginertia="0.0365586 0.0344692 0.00399326" />
                                <joint name="Rev8" pos="0 0 0" axis="0.998118 -0.0222753 0.0571384" limited="true" range="-3.14159 3.14159" />
                                <geom pos="-0.936829 -2.01107 0.487825" type="mesh" rgba="0.7 0.7 0.7 1" mesh="link_05v1_1_3dless_com_simplified" />
                                <body name="link_06v1_1" pos="0.199564 0.123078 0.0114243">
                                    <inertial pos="-0.0249529 0.000556882 -0.00142846" quat="-0.157502 0.667188 -0.167271 0.708571" mass="0.311919" diaginertia="9.31346e-05 9.3e-05 5.58654e-05" />
                                    <geom pos="-1.13639 -2.13414 0.476401" type="mesh" rgba="0.7 0.7 0.7 1" mesh="link_06v1_1" />
                                </body>
                            </body>
                        </body>
                    </body>
                </body>
            </body>
        </body>
    </worldbody>
</mujoco>
