<mujoco model="dyros_avatar_haptic">
    <option timestep='0.0005' iterations="50" tolerance="1e-5" solver="Newton" jacobian="dense" cone="elliptic" noslip_iterations="30" noslip_tolerance="1e-5"/>
    <compiler angle="radian" meshdir="../meshes/" />
    <size njmax="500" nconmax="100" />

    <default>
        <default class="prismatic_friction_joint">
            <joint damping="1.0" frictionloss="3.0"/>
        </default>
        <default class="friction_joint">
            <joint damping="1.0" frictionloss="1.0"/>
        </default>
    </default>

    <asset>
        <mesh name="R0v2_1_reduced" file="R0v2_1_reduced.stl" scale="0.001 0.001 0.001" />
        <mesh name="R1v2_1_reduced" file="R1v2_1_reduced.stl" scale="0.001 0.001 0.001" />
        <mesh name="R2v2_1_reduced" file="R2v2_1_reduced.stl" scale="0.001 0.001 0.001" />
        <mesh name="R3v2_1_reduced" file="R3v2_1_reduced.stl" scale="0.001 0.001 0.001" />
        <mesh name="R4v1_1_reduced" file="R4v1_1_reduced.stl" scale="0.001 0.001 0.001" />
        <mesh name="R5v3_1_reduced" file="R5v3_1_reduced.stl" scale="0.001 0.001 0.001" />
        <mesh name="R6v1_1_reduced" file="R6v1_1_reduced.stl" scale="0.001 0.001 0.001" />
        <mesh name="L0v1_1_reduced" file="L0v1_1_reduced.stl" scale="0.001 0.001 0.001" />
        <mesh name="L1v4_1_reduced" file="L1v4_1_reduced.stl" scale="0.001 0.001 0.001" />
        <mesh name="L2v2_1_reduced" file="L2v2_1_reduced.stl" scale="0.001 0.001 0.001" />
        <mesh name="L3v2_1_reduced" file="L3v2_1_reduced.stl" scale="0.001 0.001 0.001" />
        <mesh name="L4v5_1_reduced" file="L4v5_1_reduced.stl" scale="0.001 0.001 0.001" />
        <mesh name="L5v6_1_reduced" file="L5v6_1_reduced.stl" scale="0.001 0.001 0.001" />
        <mesh name="L6v5_1_reduced" file="L6v5_1_reduced.stl" scale="0.001 0.001 0.001" />

        <material name='MatPlane' reflectance='0.3' />
    </asset>
    <worldbody>
        <geom name="ground" type="plane" pos="0 0 0" size="30 30 .05" rgba="0.7 0.6 0.5 1" material="MatPlane" group="3"/>      
        <light directional="true" diffuse=".8 .8 .8" pos="0 0 10" dir="0 0 -10"/>
        <light directional="true" diffuse=".5 .5 .5" pos="10 0 0" dir="-10 0 0"/>

        <body name="R0v2_1" pos="0 -0.5 0.0">
            <inertial pos="-0.022028950404033087 0.05827830226084317 0.4460709796209712" quat="1.0 0 0 0" mass="54.47494543793283" fullinertia="17.852652 18.178648 1.124692 -0.098729 -0.067986 -0.126587" />
            <geom type="mesh" contype="0" conaffinity="0" group="1" rgba="0.7 0.7 0.7 1" mesh="R0v2_1_reduced" />
            <body name="R1v2_1" pos="0 0 0.4787">
                <inertial pos="0.0717487 0.0574826 0.104255" quat="0.647885 0.174867 0.191983 0.716107" mass="9.60061" diaginertia="0.22996 0.208538 0.0412995" />
                <joint name="R_Pris1" pos="0 0 0" axis="0 0 1" type="slide" limited="true" range="-3.14159 3.14159" class="prismatic_friction_joint" />
                <geom pos="0 0 -0.4787" type="mesh" contype="0" conaffinity="0" group="1" rgba="0.7 0.7 0.7 1" mesh="R1v2_1_reduced" />
                <geom pos="0 0 -0.4787" type="mesh" rgba="0.7 0.7 0.7 1" mesh="R1v2_1_reduced" />
                <body name="R2v2_1" pos="0.258548 0.0640394 0.2868">
                    <inertial pos="0.358296 -0.042077 0.00342507" quat="0.52548 0.495989 0.513329 0.46299" mass="3.64002" diaginertia="0.0891964 0.0879893 0.00492132" />
                    <joint name="R_Rev2" pos="0 0 0" axis="0 0 1" limited="true" range="-3.14159 3.14159" class="friction_joint" />
                    <geom pos="-0.258548 -0.0640394 -0.7655" type="mesh" contype="0" conaffinity="0" group="1" rgba="0.7 0.7 0.7 1" mesh="R2v2_1_reduced" />
                    <geom pos="-0.258548 -0.0640394 -0.7655" type="mesh" rgba="0.7 0.7 0.7 1" mesh="R2v2_1_reduced" />
                    <body name="R3v2_1" pos="0.497989 -0.0451167 0.0545">
                        <inertial pos="0.329929 0.124213 0.0215818" quat="-0.193551 0.682397 0.153693 0.687932" mass="2.2756" diaginertia="0.0627042 0.0598099 0.00577589" />
                        <joint name="R_Rev3" pos="0 0 0" axis="0 0 1" limited="true" range="-3.14159 3.14159" class="friction_joint" />
                        <geom pos="-0.756537 -0.0189228 -0.82" type="mesh" contype="0" conaffinity="0" group="1" rgba="0.7 0.7 0.7 1" mesh="R3v2_1_reduced" />
                        <geom pos="-0.756537 -0.0189228 -0.82" type="mesh" rgba="0.7 0.7 0.7 1" mesh="R3v2_1_reduced" />
                        <body name="R4v1_1" pos="0.410203 0.185051 -0.0103">
                            <inertial pos="0.0327339 -0.078436 -0.340309" quat="0.99209 0.0604875 -0.0650108 -0.0887239" mass="2.66166" diaginertia="0.440382 0.433739 0.00882576" />
                            <joint name="R_Rev4" pos="0 0 0" axis="0 0 1" limited="true" range="-3.14159 3.14159" class="friction_joint" />
                            <geom pos="-1.16674 -0.203973 -0.8097" type="mesh" contype="0" conaffinity="0" group="1" rgba="0.7 0.7 0.7 1" mesh="R4v1_1_reduced" />
                            <geom pos="-1.16674 -0.203973 -0.8097" type="mesh" rgba="0.7 0.7 0.7 1" mesh="R4v1_1_reduced" />
                            <body name="R5v3_1" pos="-9.61814e-05 -0.0877749 -0.156075">
                                <inertial pos="0.00347821 0.0718146 0.0123912" quat="0.667082 0.258954 -0.359381 0.598991" mass="1.64998" diaginertia="0.00367065 0.00325685 0.0025555" />
                                <joint name="R_Rev5" pos="0 0 0" axis="0.00109577 0.999999 0" limited="true" range="-3.14159 3.14159" class="friction_joint" />
                                <geom pos="-1.16664 -0.116198 -0.653625" type="mesh" contype="0" conaffinity="0" group="1" rgba="0.7 0.7 0.7 1" mesh="R5v3_1_reduced" />
                                <geom pos="-1.16664 -0.116198 -0.653625" type="mesh" rgba="0.7 0.7 0.7 1" mesh="R5v3_1_reduced" />
                                <body name="R6v1_1" pos="-0.0379044 0.0872416 0">
                                    <inertial pos="0.0265991 0.00616031 -0.0453767" quat="-0.235433 0.833026 -0.0365204 0.499305" mass="0.290033" diaginertia="0.000343672 0.000319344 0.000125984" />
                                    <joint name="R_Rev6" pos="0 0 0" axis="0.999999 -0.00109577 0" limited="true" range="-3.14159 3.14159" class="friction_joint" />
                                    <geom pos="-1.12874 -0.20344 -0.653625" type="mesh" contype="0" conaffinity="0" group="1" rgba="0.7 0.7 0.7 1" mesh="R6v1_1_reduced" />
                                    <geom pos="-1.12874 -0.20344 -0.653625" type="mesh" rgba="0.7 0.7 0.7 1" mesh="R6v1_1_reduced" />
                                </body>
                            </body>
                        </body>
                    </body>
                </body>
            </body>
        </body>

        <body name="L0v2_1" pos="0 0.5 0.0">
            <inertial pos="-0.05396861611301294 -0.03632116085286392 0.46986294658671324" quat="1.0 0 0 0" mass="83.96706134148887" fullinertia="24.453447 25.002911 1.749241 0.350866 0.742595 -1.055886" />
            <geom type="mesh" contype="0" conaffinity="0" group="1" rgba="0.7 0.7 0.7 1" mesh="L0v1_1_reduced" />
            <body name="L1v4_1" pos="0 0 0.4777">
                <inertial pos="0.0741768 -0.0573319 0.10445" quat="0.709809 0.206102 0.184098 0.647921" mass="9.31131" diaginertia="0.214559 0.192957 0.0403377" />
                <joint name="L_Pris1" pos="0 0 0" axis="0 0 1" type="slide" limited="true" range="-3.14159 3.14159" class="prismatic_friction_joint" />
                <geom pos="0 0 -0.4777" type="mesh" contype="0" conaffinity="0" group="1" rgba="0.7 0.7 0.7 1" mesh="L1v4_1_reduced" />
                <geom pos="0 0 -0.4777" type="mesh" rgba="0.7 0.7 0.7 1" mesh="L1v4_1_reduced" />
                <body name="L2v2_1" pos="0.2585 -0.0640996 0.2763">
                    <inertial pos="0.367464 0.0422953 0.0036939" quat="0.466196 0.511276 0.496376 0.52428" mass="3.78943" diaginertia="0.0897107 0.0884485 0.00513988" />
                    <joint name="L_Rev2" pos="0 0 0" axis="0 0 1" limited="true" range="-3.14159 3.14159" class="friction_joint" />
                    <geom pos="-0.2585 0.0640996 -0.754" type="mesh" contype="0" conaffinity="0" group="1" rgba="0.7 0.7 0.7 1" mesh="L2v2_1_reduced" />
                    <geom pos="-0.2585 0.0640996 -0.754" type="mesh" rgba="0.7 0.7 0.7 1" mesh="L2v2_1_reduced" />
                    <body name="L3v2_1" pos="0.498 0.0450008 0.0545">
                        <inertial pos="0.332053 -0.125922 0.021879" quat="0.196811 0.682329 -0.153195 0.687186" mass="2.21888" diaginertia="0.0598933 0.0571596 0.00560508" />
                        <joint name="L_Rev3" pos="0 0 0" axis="0 0 1" limited="true" range="-3.14159 3.14159" class="friction_joint" />
                        <geom pos="-0.7565 0.0190989 -0.8085" type="mesh" contype="0" conaffinity="0" group="1" rgba="0.7 0.7 0.7 1" mesh="L3v2_1_reduced" />
                        <geom pos="-0.7565 0.0190989 -0.8085" type="mesh" rgba="0.7 0.7 0.7 1" mesh="L3v2_1_reduced" />
                        <body name="L4v5_1" pos="0.41 -0.185499 -0.0103">
                            <inertial pos="0.0427469 0.127859 -0.336244" quat="0.987305 0.041506 -0.0976902 0.118161" mass="2.66166" diaginertia="0.428558 0.424968 0.0064434" />
                            <joint name="L_Rev4" pos="0 0 0" axis="0 0 1" limited="true" range="-3.14159 3.14159" class="friction_joint" />
                            <geom pos="-1.1665 0.204598 -0.7982" type="mesh" contype="0" conaffinity="0" group="1" rgba="0.7 0.7 0.7 1" mesh="L4v5_1_reduced" />
                            <geom pos="-1.1665 0.204598 -0.7982" type="mesh" rgba="0.7 0.7 0.7 1" mesh="L4v5_1_reduced" />
                            <body name="L5v6_1" pos="-1.32706e-07 0.087775 -0.156075">
                                <inertial pos="0.00399252 -0.0718382 0.0123912" quat="0.249857 0.668142 -0.596578 0.367767" mass="1.64998" diaginertia="0.00367353 0.0032645 0.00255196" />
                                <joint name="L_Rev5" pos="0 0 0" axis="1.51189e-06 -1 0" limited="true" range="-3.14159 3.14159" class="friction_joint" />
                                <geom pos="-1.1665 0.116823 -0.642125" type="mesh" contype="0" conaffinity="0" group="1" rgba="0.7 0.7 0.7 1" mesh="L5v6_1_reduced" />
                                <geom pos="-1.1665 0.116823 -0.642125" type="mesh" rgba="0.7 0.7 0.7 1" mesh="L5v6_1_reduced" />
                                <body name="L6v5_1" pos="-0.0371999 -0.0872001 0">
                                    <inertial pos="0.0265923 0.0061895 -0.0453767" quat="-0.237082 0.832131 -0.0374919 0.499944" mass="0.290033" diaginertia="0.000342861 0.000319494 0.000126645" />
                                    <joint name="L_Rev6" pos="0 0 0" axis="1 1.51189e-06 0" limited="true" range="-3.14159 3.14159" class="friction_joint" />
                                    <geom pos="-1.1293 0.204023 -0.642125" type="mesh" contype="0" conaffinity="0" group="1" rgba="0.7 0.7 0.7 1" mesh="L6v5_1_reduced" />
                                    <geom pos="-1.1293 0.204023 -0.642125" type="mesh" rgba="0.7 0.7 0.7 1" mesh="L6v5_1_reduced" />
                                </body>
                            </body>
                        </body>
                    </body>
                </body>
            </body>
        </body>
    </worldbody>

    <actuator>
        <motor name="R_Prismatic1" joint="R_Pris1" ctrlrange="-500 500"/>
        <motor name="R_Revolute2" joint="R_Rev2" ctrlrange="-100 100"/>
        <motor name="R_Revolute3" joint="R_Rev3" ctrlrange="-100 100"/>
        <motor name="R_Revolute4" joint="R_Rev4" ctrlrange="-100 100"/>
        <motor name="R_Revolute5" joint="R_Rev5" ctrlrange="-100 100"/>
        <motor name="R_Revolute6" joint="R_Rev6" ctrlrange="-100 100"/>

        <motor name="L_Prismatic1" joint="L_Pris1" ctrlrange="-500 500"/>
        <motor name="L_Revolute2" joint="L_Rev2" ctrlrange="-100 100"/>
        <motor name="L_Revolute3" joint="L_Rev3" ctrlrange="-100 100"/>
        <motor name="L_Revolute4" joint="L_Rev4" ctrlrange="-100 100"/>
        <motor name="L_Revolute5" joint="L_Rev5" ctrlrange="-100 100"/>
        <motor name="L_Revolute6" joint="L_Rev6" ctrlrange="-100 100"/>
    </actuator>

    <keyframe>
        <key name="front" time="0" qpos ="0.0 -0.8 1.6 -0.8 0.0 -1.57
                                        0.0 0.8 -1.6 0.8 0.0 1.57"/>
    </keyframe>
</mujoco>
